Workbook

Sheet Lead Tracker
A1: FORREST ANALYTICS GROUP LLC — CLIENT PIPELINE
A2: ID | B2: First Name | C2: Last Name | D2: Institution | E2: PhD Field | F2: Fit | G2: Priority | H2: Email | I2: Date Added | J2: Date Contacted | K2: Follow-up Sent | L2: Status | M2: Last Contact | N2: Next Follow-Up | O2: Notes | P2: Est. Value ($) | Q2: Actual Rev ($) | R2: Days Since Contact | S2: Source
A3: 1 | B3: Existing | C3: Client | D3: Duquesne University | E3: Psychology PhD | F3: High | G3: High | H3: client@duq.edu | I3: 2025-07-01 | J3: 2026-03-15 | K3: YES | L3: Active Client | M3: 2026-03-15 | O3: Race IAT study — full delivery. Request referrals. | P3: 4500 | Q3: 4500 | R3: =IF(J3="","",TODAY()-DATE(LEFT(J3,4)*1,MID(J3,6,2)*1,RIGHT(J3,2)*1))
A4: 2 | B4: Department | C4: Head | D4: Thomas Jefferson University | E4: Nursing PhD | F4: High | G4: High | I4: 2026-04-02 | J4: 2026-04-02 | K4: YES | L4: Nurture | M4: 2026-04-02 | N4: 2026-07-01 | O4: First dissertations ~1 year out. Quarterly check-in. | P4: 3000 | Q4: 0 | R4: =IF(J4="","",TODAY()-DATE(LEFT(J4,4)*1,MID(J4,6,2)*1,RIGHT(J4,2)*1))
A5: 3 | B5: Tory | C5: Benson | D5: Rutgers University - New Brunswick | E5: Social Psychology | F5: High | G5: High | H5: tgb54@scarletmail.rutgers.edu | I5: 2026-04-02 | J5: 2026-04-02 | K5: YES | L5: Contacted | M5: 2026-04-02 | P5: 2500 | Q5: 0 | R5: =IF(J5="","",TODAY()-DATE(LEFT(J5,4)*1,MID(J5,6,2)*1,RIGHT(J5,2)*1))
A6: 4 | B6: Noah | C6: Booker | D6: Rutgers University - New Brunswick | E6: Social Psychology | F6: High | G6: High | H6: nb1157@rutgers.edu | I6: 2026-04-02 | K6: NO | L6: New Lead | P6: 2500 | Q6: 0 | R6: =IF(J6="","",TODAY()-DATE(LEFT(J6,4)*1,MID(J6,6,2)*1,RIGHT(J6,2)*1))
A7: 5 | B7: Clara | C7: Civiero | D7: Rutgers University - New Brunswick | E7: Social Psychology | F7: High | G7: High | H7: clara.civiero@rutgers.edu | I7: 2026-04-02 | K7: NO | L7: New Lead | P7: 2500 | Q7: 0 | R7: =IF(J7="","",TODAY()-DATE(LEFT(J7,4)*1,MID(J7,6,2)*1,RIGHT(J7,2)*1))
A8: 6 | B8: William | C8: Coleman | D8: Rutgers University - New Brunswick | E8: Social Psychology | F8: High | G8: High | H8: willy.coleman@rutgers.edu | I8: 2026-04-02 | K8: NO | L8: New Lead | P8: 2500 | Q8: 0 | R8: =IF(J8="","",TODAY()-DATE(LEFT(J8,4)*1,MID(J8,6,2)*1,RIGHT(J8,2)*1))
A9: 7 | B9: Erin | C9: Foy | D9: Rutgers University - New Brunswick | E9: Social Psychology | F9: High | G9: High | H9: erin.foy@rutgers.edu | I9: 2026-04-02 | K9: NO | L9: New Lead | P9: 2500 | Q9: 0 | R9: =IF(J9="","",TODAY()-DATE(LEFT(J9,4)*1,MID(J9,6,2)*1,RIGHT(J9,2)*1))
A10: 8 | B10: Tamara | C10: Franklin | D10: Rutgers University - New Brunswick | E10: Social Psychology | F10: High | G10: High | H10: tamara.franklin@rutgers.edu | I10: 2026-04-02 | K10: NO | L10: New Lead | P10: 2500 | Q10: 0 | R10: =IF(J10="","",TODAY()-DATE(LEFT(J10,4)*1,MID(J10,6,2)*1,RIGHT(J10,2)*1))
A11: 9 | B11: Vanessa | C11: Hatton | D11: Rutgers University - New Brunswick | E11: Social Psychology | F11: High | G11: High | H11: v.hatton@rutgers.edu | I11: 2026-04-02 | K11: NO | L11: New Lead | P11: 2500 | Q11: 0 | R11: =IF(J11="","",TODAY()-DATE(LEFT(J11,4)*1,MID(J11,6,2)*1,RIGHT(J11,2)*1))
A12: 10 | B12: Selin | C12: Toprakkiran | D12: Rutgers University - New Brunswick | E12: Social Psychology | F12: High | G12: High | H12: selin.t@rutgers.edu | I12: 2026-04-02 | K12: NO | L12: New Lead | P12: 2500 | Q12: 0 | R12: =IF(J12="","",TODAY()-DATE(LEFT(J12,4)*1,MID(J12,6,2)*1,RIGHT(J12,2)*1))
A13: 11 | B13: Grace | C13: Wetzel | D13: Rutgers University - New Brunswick | E13: Social Psychology | F13: High | G13: High | H13: grace.wetzel@rutgers.edu | I13: 2026-04-02 | K13: NO | L13: New Lead | P13: 2500 | Q13: 0 | R13: =IF(J13="","",TODAY()-DATE(LEFT(J13,4)*1,MID(J13,6,2)*1,RIGHT(J13,2)*1))
A14: 12 | B14: Sandra | C14: Manfreda | D14: Rutgers University - New Brunswick | E14: Social Psychology | F14: High | G14: High | H14: sandra.manfreda@rutgers.edu | I14: 2026-04-02 | K14: NO | L14: New Lead | P14: 2500 | Q14: 0 | R14: =IF(J14="","",TODAY()-DATE(LEFT(J14,4)*1,MID(J14,6,2)*1,RIGHT(J14,2)*1))
A15: 13 | B15: Alyssa | C15: Gagnon | D15: Rutgers University | E15: Well-Being Psychology | F15: High | G15: High | H15: alyssa.gagnon@rutgers.edu | I15: 2026-04-02 | J15: 2026-04-02 | K15: YES | L15: Contacted | M15: 2026-04-02 | P15: 2500 | Q15: 0 | R15: =IF(J15="","",TODAY()-DATE(LEFT(J15,4)*1,MID(J15,6,2)*1,RIGHT(J15,2)*1))
A16: 14 | B16: Rowan | C16: Kemmerly | D16: Rutgers University | E16: Well-Being Psychology | F16: High | G16: High | H16: rek102@psychology.rutgers.edu | I16: 2026-04-02 | K16: NO | L16: New Lead | P16: 2500 | Q16: 0 | R16: =IF(J16="","",TODAY()-DATE(LEFT(J16,4)*1,MID(J16,6,2)*1,RIGHT(J16,2)*1))
A17: 15 | B17: Elif | C17: Ulutas | D17: Rutgers University | E17: Well-Being / Health Psychology | F17: High | G17: High | H17: elif.ulutas@rutgers.edu | I17: 2026-04-02 | K17: NO | L17: New Lead | P17: 2500 | Q17: 0 | R17: =IF(J17="","",TODAY()-DATE(LEFT(J17,4)*1,MID(J17,6,2)*1,RIGHT(J17,2)*1))
A18: 16 | B18: Romi | C18: Paldi | D18: Rutgers University | E18: Social Development | F18: Medium | G18: High | H18: romi.paldi@rutgers.edu | I18: 2026-04-02 | K18: NO | L18: New Lead | P18: 2500 | Q18: 0 | R18: =IF(J18="","",TODAY()-DATE(LEFT(J18,4)*1,MID(J18,6,2)*1,RIGHT(J18,2)*1))
A19: 17 | B19: Mary | C19: Mousa | D19: Rutgers University | E19: Social Psychology | F19: High | G19: High | H19: msm299@rutgers.edu | I19: 2026-04-02 | K19: NO | L19: New Lead | P19: 2500 | Q19: 0 | R19: =IF(J19="","",TODAY()-DATE(LEFT(J19,4)*1,MID(J19,6,2)*1,RIGHT(J19,2)*1))
A20: 18 | B20: Sarah | C20: Zhong | D20: Rutgers University | E20: Social Psychology | F20: High | G20: High | H20: yining.zhong@rutgers.edu | I20: 2026-04-02 | K20: NO | L20: New Lead | P20: 2500 | Q20: 0 | R20: =IF(J20="","",TODAY()-DATE(LEFT(J20,4)*1,MID(J20,6,2)*1,RIGHT(J20,2)*1))
A21: 19 | B21: Amanda | C21: Nyakwada | D21: Rutgers University | E21: Decision-Making Psychology | F21: High | G21: High | H21: amanda.nyakwada@rutgers.edu | I21: 2026-04-02 | K21: NO | L21: New Lead | P21: 2500 | Q21: 0 | R21: =IF(J21="","",TODAY()-DATE(LEFT(J21,4)*1,MID(J21,6,2)*1,RIGHT(J21,2)*1))
A22: 20 | B22: Darian | C22: Raizberg | D22: Rutgers University | E22: Decision-Making Psychology | F22: High | G22: High | H22: darian.raizberg@rutgers.edu | I22: 2026-04-02 | K22: NO | L22: New Lead | P22: 2500 | Q22: 0 | R22: =IF(J22="","",TODAY()-DATE(LEFT(J22,4)*1,MID(J22,6,2)*1,RIGHT(J22,2)*1))
A23: 21 | B23: Larissa | C23: Allen | D23: University of Pittsburgh | E23: Nursing / Suicide Research | F23: High | G23: High | H23: lca16@pitt.edu | I23: 2026-04-02 | J23: 2026-04-02 | K23: YES | L23: Contacted | M23: 2026-04-02 | P23: 2500 | Q23: 0 | R23: =IF(J23="","",TODAY()-DATE(LEFT(J23,4)*1,MID(J23,6,2)*1,RIGHT(J23,2)*1))
A24: 22 | B24: Katherine | C24: Cahir | D24: University of Pittsburgh | E24: Nursing / Health Equity | F24: High | G24: High | H24: kmc294@pitt.edu | I24: 2026-04-02 | K24: NO | L24: New Lead | P24: 2500 | Q24: 0 | R24: =IF(J24="","",TODAY()-DATE(LEFT(J24,4)*1,MID(J24,6,2)*1,RIGHT(J24,2)*1))
A25: 23 | B25: Sondos | C25: Eqylan | D25: University of Pittsburgh | E25: Nursing / Caregiving Science | F25: High | G25: High | H25: sbe14@pitt.edu | I25: 2026-04-02 | K25: NO | L25: New Lead | P25: 2500 | Q25: 0 | R25: =IF(J25="","",TODAY()-DATE(LEFT(J25,4)*1,MID(J25,6,2)*1,RIGHT(J25,2)*1))
A26: 24 | B26: Emily | C26: He | D26: University of Pittsburgh | E26: Nursing / Health Equity | F26: High | G26: High | H26: esh87@pitt.edu | I26: 2026-04-02 | K26: NO | L26: New Lead | P26: 2500 | Q26: 0 | R26: =IF(J26="","",TODAY()-DATE(LEFT(J26,4)*1,MID(J26,6,2)*1,RIGHT(J26,2)*1))
A27: 25 | B27: Rezvaneh | C27: Manzour | D27: University of Pittsburgh | E27: Nursing / Mental Health | F27: High | G27: High | H27: rem302@pitt.edu | I27: 2026-04-02 | K27: NO | L27: New Lead | P27: 2500 | Q27: 0 | R27: =IF(J27="","",TODAY()-DATE(LEFT(J27,4)*1,MID(J27,6,2)*1,RIGHT(J27,2)*1))
A28: 26 | B28: Mercy | C28: Opateye | D28: University of Pittsburgh | E28: Nursing / Maternal & Child Health | F28: High | G28: High | H28: mao268@pitt.edu | I28: 2026-04-02 | K28: NO | L28: New Lead | P28: 2500 | Q28: 0 | R28: =IF(J28="","",TODAY()-DATE(LEFT(J28,4)*1,MID(J28,6,2)*1,RIGHT(J28,2)*1))
A29: 27 | B29: Morteza | C29: Shamsizadeh | D29: University of Pittsburgh | E29: Nursing / Palliative Care | F29: High | G29: High | H29: mortyzadeh@pitt.edu | I29: 2026-04-02 | K29: NO | L29: New Lead | P29: 2500 | Q29: 0 | R29: =IF(J29="","",TODAY()-DATE(LEFT(J29,4)*1,MID(J29,6,2)*1,RIGHT(J29,2)*1))
A30: 28 | B30: Kai-Lin | C30: You | D30: University of Pittsburgh | E30: Nursing / Cancer Survivorship | F30: High | G30: High | H30: kailinyou@pitt.edu | I30: 2026-04-02 | K30: NO | L30: New Lead | P30: 2500 | Q30: 0 | R30: =IF(J30="","",TODAY()-DATE(LEFT(J30,4)*1,MID(J30,6,2)*1,RIGHT(J30,2)*1))
A31: 29 | B31: Oluwadunsin | C31: (Esther) Akingbasote | D31: Penn State University | E31: Nursing / Health Equity | F31: High | G31: High | H31: kea5558@psu.edu | I31: 2026-04-02 | J31: 2026-04-02 | K31: YES | L31: Contacted | M31: 2026-04-02 | P31: 2500 | Q31: 0 | R31: =IF(J31="","",TODAY()-DATE(LEFT(J31,4)*1,MID(J31,6,2)*1,RIGHT(J31,2)*1))
A32: 30 | B32: Nahida | C32: Akter | D32: Penn State University | E32: Nursing / Global Health | F32: High | G32: High | H32: nfa5307@psu.edu | I32: 2026-04-02 | K32: NO | L32: New Lead | P32: 2500 | Q32: 0 | R32: =IF(J32="","",TODAY()-DATE(LEFT(J32,4)*1,MID(J32,6,2)*1,RIGHT(J32,2)*1))
A33: 31 | B33: John | C33: Akudugu | D33: Penn State University | E33: Nursing / Public Health | F33: High | G33: High | H33: jma7189@psu.edu | I33: 2026-04-02 | K33: NO | L33: New Lead | P33: 2500 | Q33: 0 | R33: =IF(J33="","",TODAY()-DATE(LEFT(J33,4)*1,MID(J33,6,2)*1,RIGHT(J33,2)*1))
A34: 32 | B34: Samiya | C34: Al Hadhrami | D34: Penn State University | E34: Nursing / Health Services | F34: High | G34: High | H34: sma7174@psu.edu | I34: 2026-04-02 | K34: NO | L34: New Lead | P34: 2500 | Q34: 0 | R34: =IF(J34="","",TODAY()-DATE(LEFT(J34,4)*1,MID(J34,6,2)*1,RIGHT(J34,2)*1))
A35: 33 | B35: Habiba | C35: AL Manji | D35: Penn State University | E35: Nursing / Caregiving | F35: High | G35: High | H35: hpa5265@psu.edu | I35: 2026-04-02 | K35: NO | L35: New Lead | P35: 2500 | Q35: 0 | R35: =IF(J35="","",TODAY()-DATE(LEFT(J35,4)*1,MID(J35,6,2)*1,RIGHT(J35,2)*1))
A36: 34 | B36: Comfort | C36: Asare | D36: Penn State University | E36: Nursing / Maternal & Child Health | F36: High | G36: High | H36: cma6410@psu.edu | I36: 2026-04-02 | K36: NO | L36: New Lead | P36: 2500 | Q36: 0 | R36: =IF(J36="","",TODAY()-DATE(LEFT(J36,4)*1,MID(J36,6,2)*1,RIGHT(J36,2)*1))
A37: 35 | B37: Thakshila | C37: Dasanayake | D37: Penn State University | E37: Nursing / Behavioral Health | F37: High | G37: High | H37: tsd5277@psu.edu | I37: 2026-04-02 | K37: NO | L37: New Lead | P37: 2500 | Q37: 0 | R37: =IF(J37="","",TODAY()-DATE(LEFT(J37,4)*1,MID(J37,6,2)*1,RIGHT(J37,2)*1))
A38: 36 | B38: Myra | C38: DeLuca | D38: Penn State University | E38: Nursing / Clinical Outcomes | F38: High | G38: High | H38: mjj113@psu.edu | I38: 2026-04-02 | K38: NO | L38: New Lead | P38: 2500 | Q38: 0 | R38: =IF(J38="","",TODAY()-DATE(LEFT(J38,4)*1,MID(J38,6,2)*1,RIGHT(J38,2)*1))
A39: 37 | B39: Stephanie | C39: Gigous | D39: Penn State University | E39: Nursing / Health Research | F39: High | G39: High | H39: sln132@psu.edu | I39: 2026-04-02 | K39: NO | L39: New Lead | P39: 2500 | Q39: 0 | R39: =IF(J39="","",TODAY()-DATE(LEFT(J39,4)*1,MID(J39,6,2)*1,RIGHT(J39,2)*1))
A40: 38 | B40: Donya | C40: Hafezi Nia | D40: Penn State University | E40: Nursing / Health Informatics | F40: High | G40: High | H40: djh6767@psu.edu | I40: 2026-04-02 | K40: NO | L40: New Lead | P40: 2500 | Q40: 0 | R40: =IF(J40="","",TODAY()-DATE(LEFT(J40,4)*1,MID(J40,6,2)*1,RIGHT(J40,2)*1))
...

Sheet Email Templates
A1: FORREST ANALYTICS GROUP LLC — OUTREACH EMAIL TEMPLATES
A2: FORMAT RULES: 50-125 words max | 3-7 word subject | One CTA question | No em dashes | No bullets | Sound human | Link website naturally
A3: TEMPLATE 1 -- Cold Outreach - Psychology / Social Psych PhD | B3: Cold Outreach -- Psychology / Social Psych PhD
A4: Subject | B4: quick question about your dissertation
A5: Body | B5: Hi [First Name], I came across your profile through the [University] psychology program and wanted to reach out. I run Forrest Analytics Group (forrestanalyticsgroup.com) and I help PhD candidates with the data side of dissertations -- things like Qualtrics setup, R or Python analysis, and the stats for the results chapter. I just finished a project like that for a psych PhD candidate at Duquesne and it went really well. Are you at a stage where that kind of support might be useful? Josh Forrest 856.725.4983
A6: Word Count | B6: ~75 words
A8: TEMPLATE 2 -- Cold Outreach - Nursing / Public Health PhD | B8: Cold Outreach -- Nursing / Public Health PhD
A9: Subject | B9: dissertation data support -- nursing research
A10: Body | B10: Hi [First Name], I found you through the [University] nursing program and wanted to reach out. I work with nursing and public health PhD candidates on the technical parts of their dissertations -- Qualtrics survey setup, data cleaning in R, and statistical analysis for the results chapter. I run Forrest Analytics Group (forrestanalyticsgroup.com) and recently completed a full data support project for another doctoral candidate. Are you approaching your data collection or analysis phase? Josh Forrest 856.725.4983
A11: Word Count | B11: ~80 words
A13: TEMPLATE 3 -- Cold Outreach - Behavior Analysis / Clinical Science | B13: Cold Outreach -- Behavior Analysis / Clinical Science
A14: Subject | B14: data help for your dissertation
A15: Body | B15: Hi [First Name], I run Forrest Analytics Group (forrestanalyticsgroup.com) and work with doctoral candidates on the technical parts of dissertation research -- survey design, data cleaning, and statistical analysis in R and Python. I found you through the [University] program and thought this might be relevant to where you are in your research. I recently supported a PhD candidate at Duquesne through the full analysis phase. Would a quick 15-minute call be worth it? Josh Forrest 856.725.4983
A16: Word Count | B16: ~80 words
... A36: Word Count | B36: ~55 words

Sheet Dashboard
A1: PIPELINE DASHBOARD
A3: PIPELINE SUMMARY
A4: Metric | B4: Count | C4: Est. Value ($) | D4: Actual Rev ($)
A5: Total Leads | B5: =COUNTA('Lead Tracker'!A3:A2000) | C5: =SUMIF('Lead Tracker'!L3:L2000,"<>Closed Lost",'Lead Tracker'!P3:P2000) | D5: =SUM('Lead Tracker'!Q3:Q2000)
A6: High Priority | B6: =COUNTIF('Lead Tracker'!G3:G2000,"High")
A7: New (Not Contacted) | B7: =COUNTIF('Lead Tracker'!L3:L2000,"New Lead")
A8: Contacted | B8: =COUNTIF('Lead Tracker'!L3:L2000,"Contacted")
A9: Active Clients | B9: =COUNTIF('Lead Tracker'!L3:L2000,"Active Client") | C9: =SUMIF('Lead Tracker'!L3:L2000,"Active Client",'Lead Tracker'!P3:P2000) | D9: =SUMIF('Lead Tracker'!L3:L2000,"Active Client",'Lead Tracker'!Q3:Q2000)
A10: Closed Won | B10: =COUNTIF('Lead Tracker'!L3:L2000,"Closed Won") | D10: =SUMIF('Lead Tracker'!L3:L2000,"Closed Won",'Lead Tracker'!Q3:Q2000)
A11: Nurture | B11: =COUNTIF('Lead Tracker'!L3:L2000,"Nurture")
A14: REVENUE GOALS
A15: Monthly Revenue Target ($) | B15: 2000
A16: Total Actual Revenue ($) | B16: =SUM('Lead Tracker'!Q3:Q2000)
A17: Total Pipeline Value ($) | B17: =SUMIF('Lead Tracker'!L3:L2000,"<>Closed Lost",'Lead Tracker'!P3:P2000)
A20: LEAD PRIORITY BREAKDOWN
A21: High Priority Leads | B21: =COUNTIF('Lead Tracker'!G3:G2000,"High")
A22: Medium Priority Leads | B22: =COUNTIF('Lead Tracker'!G3:G2000,"Medium")
A23: Low Priority Leads | B23: =COUNTIF('Lead Tracker'!G3:G2000,"Low")
