Workbook

Sheet README
A1: KEYSTONE PLUMBING & DRAIN — Sample Operational Dataset
A3: Prepared by: Forrest Analytics Group LLC
A4: Use: Case-study dataset for AI implementation portfolio (service-business vertical)
A5: Generated: 2026-04-07
A7: Business profile (fictional):
A8: • Founded 2014, Philadelphia metro (Main Line + Western Suburbs)
A9: • 8 technicians, 5 service trucks, ~$2.1M annual revenue
A10: • Mix: ~75% residential, ~15% commercial, ~10% property mgmt
A11: • Services: plumbing, drain, water heater, sewer, sump pump, light HVAC
A13: Sheets in this workbook:
A14: • Customers — 850 records (residential, commercial, property mgmt)
A15: • Jobs — 2400 records spanning ~24 months
... A21: • Summary — KPI rollup with formulas

Sheet Customers
A1: Customer ID | B1: Name | C1: Type | D1: Phone | E1: Email | F1: Address | G1: City | H1: State | I1: Zip | J1: Lead Source | K1: Created | L1: Lifetime Jobs
A2: C-10001 | B2: Christine Anderson | C2: Residential | D2: (494) 289-7912 | E2: christine.anderson30@gmail.com | F2: 509 Madison Ln | G2: King of Prussia | H2: PA | I2: 19438 | J2: Google Search | K2: 2024-03-13 | L2: 3
A3: C-10002 | B3: Brenda Sanchez | C3: Residential | D3: (572) 632-6574 | E3: brenda.sanchez98@outlook.com | F3: 9028 Garden Blvd | G3: Norristown | H3: PA | I3: 19485 | J3: Repeat Customer | K3: 2023-12-30 | L3: 3
A4: C-10003 | B4: Susan Lopez | C4: Residential | D4: (278) 587-2291 | E4: susan_lopez@comcast.net | F4: 6324 Cedar Dr | G4: Ardmore | H4: PA | I4: 19087 | J4: Angi | K4: 2024-01-01 | L4: 1
A5: C-10004 | B5: Pamela Harris | C5: Residential | D5: (540) 573-3664 | E5: pamela_harris35@outlook.com | F5: 1239 Oak Blvd | G5: Wayne | H5: PA | I5: 19020 | J5: Google Search | K5: 2023-11-01 | L5: 1
A6: C-10005 | B6: Perez Management | C6: Commercial | D6: (381) 986-1916 | E6: samantha.perez@yahoo.com | F6: 8851 Madison Blvd | G6: Conshohocken | H6: PA | I6: 19469 | J6: HomeAdvisor | K6: 2024-06-20 | L6: 1
A7: C-10006 | B7: Rodriguez Plaza | C7: Property Mgmt | D7: (341) 962-9830 | E7: paulrodriguez@outlook.com | F7: 3556 Baltimore Dr | G7: King of Prussia | H7: PA | I7: 19493 | J7: HomeAdvisor | K7: 2024-06-17 | L7: 1
A8: C-10007 | B8: George Lewis | C8: Residential | D8: (431) 810-2040 | E8: george_lewis@hotmail.com | F8: 2366 Lombard Pl | G8: Bryn Mawr | H8: PA | I8: 19016 | J8: Direct Mail | K8: 2025-11-01 | L8: 3
A9: C-10008 | B9: Allen Management | C9: Commercial | D9: (437) 361-8433 | E9: helenallen@gmail.com | F9: 9164 Franklin St | G9: West Chester | H9: PA | I9: 19324 | J9: Repeat Customer | K9: 2024-02-09 | L9: 1
A10: C-10009 | B10: Thompson Realty | C10: Commercial | D10: (491) 997-9689 | E10: nicholasthompson@gmail.com | F10: 8417 Baltimore Ave | G10: West Chester | H10: PA | I10: 19348 | J10: Google Search | K10: 2025-09-15 | L10: 3
A11: C-10010 | B11: Joseph Campbell | C11: Residential | D11: (604) 745-3060 | E11: josephcampbell@yahoo.com | F11: 5138 Spruce St | G11: King of Prussia | H11: PA | I11: 19482 | J11: Facebook | K11: 2026-01-09 | L11: 4
A12: C-10011 | B12: Kimberly Ortiz | C12: Residential | D12: (547) 582-8177 | E12: kimberly_ortiz29@comcast.net | F12: 7032 Chestnut Way | G12: Drexel Hill | H12: PA | I12: 19098 | J12: Google Search | K12: 2024-04-06 | L12: 12
A13: C-10012 | B13: Amanda Williams | C13: Residential | D13: (249) 232-6413 | E13: amandawilliams86@gmail.com | F13: 9738 Pine Blvd | G13: Media | H13: PA | I13: 19038 | J13: Truck Signage | K13: 2026-01-24 | L13: 1
... A851: C-10850 | B851: Stephanie Allen | C851: Residential | D851: (492) 432-7590 | E851: stephanieallen@yahoo.com | F851: 2726 Broad St | G851: Bala Cynwyd | H851: PA | I851: 19048 | J851: HomeAdvisor | K851: 2026-02-22 | L851: 2

Sheet Jobs
A1: Job ID | B1: Customer ID | C1: Customer Name | D1: Job Type | E1: Category | F1: Priority | G1: Scheduled | H1: Completed | I1: Status | J1: Tech ID | K1: Tech Name | L1: Hours | M1: Revenue | N1: Parts Cost | O1: Labor Cost | P1: COGS | Q1: Margin | R1: Rating | S1: City | T1: Zip
A2: J-20001 | B2: C-10432 | C2: Karen Hill | D2: Frozen Pipe Thaw | E2: Emergency | F2: Emergency | G2: 2024-05-25 11:52 | H2: 2024-05-25 11:52 | I2: Completed | J2: T-04 | K2: Brandon Pierce | L2: 1.47 | M2: 665.95 | N2: 150.91 | O2: 79.56 | P2: 230.47 | Q2: 435.48 | S2: Bryn Mawr | T2: 19091
A3: J-20002 | B3: C-10747 | C3: Michelle Hernandez | D3: Slab Leak Repair | E3: Repair | F3: Standard | G3: 2025-02-12 12:19 | H3: 2025-02-12 12:19 | I3: Completed | J3: T-08 | K3: Marcus Thompson | L3: 6.4 | M3: 3927.93 | N3: 799.67 | O3: 368.07 | P3: 1167.74 | Q3: 2760.19 | S3: Bala Cynwyd | T3: 19021
A4: J-20003 | B4: C-10794 | C4: Anthony Flores | D4: Boiler Repair | E4: HVAC | F4: Standard | G4: 2025-03-09 07:33 | H4: 2025-03-09 07:33 | I4: Completed | J4: T-07 | K4: Kevin O'Brien | L4: 2.83 | M4: 569.33 | N4: 140.56 | O4: 139.32 | P4: 279.88 | Q4: 289.45 | R4: 1 | S4: Chester | T4: 19087
A5: J-20004 | B5: C-10697 | C5: Adams Management | D5: Backflow Testing | E5: Inspection | F5: Standard | G5: 2025-09-16 19:34 | H5: 2025-09-16 19:34 | I5: Completed | J5: T-08 | K5: Marcus Thompson | L5: 0.71 | M5: 257.31 | N5: 68.83 | O5: 42.97 | P5: 111.8 | Q5: 145.51 | S5: West Chester | T5: 19357
A6: J-20005 | B6: C-10628 | C6: Cruz Group | D6: Hydro Jetting | E6: Drain | F6: Standard | G6: 2026-03-29 22:39 | H6: 2026-03-30 22:39 | I6: Completed | J6: T-04 | K6: Brandon Pierce | L6: 2.38 | M6: 763.09 | N6: 229.69 | O6: 112.61 | P6: 342.3 | Q6: 420.79 | S6: West Chester | T6: 19347
A7: J-20006 | B7: C-10315 | C7: Scott Hill | D7: Furnace Repair | E7: HVAC | F7: Standard | G7: 2025-01-04 08:39 | H7: 2025-01-04 08:39 | I7: Completed | J7: T-03 | K7: Tyrese Jackson | L7: 0.98 | M7: 275.18 | N7: 72.47 | O7: 52.45 | P7: 124.92 | Q7: 150.26 | R7: 5 | S7: Bryn Mawr | T7: 19017
A8: J-20007 | B8: C-10546 | C8: Mary Davis | D8: Water Softener Install | E8: Install | F8: Standard | G8: 2025-07-25 20:18 | H8: 2025-07-27 20:18 | I8: Completed | J8: T-01 | K8: Mike Sullivan | L8: 2.92 | M8: 2004.42 | N8: 563.18 | O8: 153.57 | P8: 716.75 | Q8: 1287.67 | R8: 5 | S8: West Chester | T8: 19384
A9: J-20008 | B9: C-10175 | C9: William Mitchell | D9: HVAC Tune-Up | E9: HVAC | F9: Standard | G9: 2025-01-10 05:24 | I9: Scheduled | J9: T-06 | K9: David Chen | L9: 1.76 | M9: 151 | N9: 42.02 | O9: 118.07 | P9: 160.09 | Q9: -9.09 | S9: West Chester | T9: 19349
A10: J-20009 | B10: C-10088 | C10: George Mitchell | D10: Sump Pump Install | E10: Install | F10: Standard | G10: 2024-05-22 17:20 | I10: Cancelled | J10: T-02 | K10: Carlos Mendez | L10: 3.37 | M10: 872.59 | N10: 183.71 | O10: 165.25 | P10: 348.96 | Q10: 523.63 | S10: Ardmore | T10: 19096
A11: J-20010 | B11: C-10819 | C11: Donna Evans | D11: Kitchen Remodel Plumbing | E11: Project | F11: Standard | G11: 2025-10-15 12:06 | I11: Scheduled | J11: T-01 | K11: Mike Sullivan | L11: 12.68 | M11: 2317.81 | N11: 753.15 | O11: 713.62 | P11: 1466.77 | Q11: 851.04 | S11: Wayne | T11: 19055
A12: J-20011 | B12: C-10171 | C12: Sarah Evans | D12: Water Heater Replacement | E12: Install | F12: Standard | G12: 2025-07-01 00:12 | H12: 2025-07-01 00:12 | I12: Completed | J12: T-01 | K12: Mike Sullivan | L12: 3.47 | M12: 1818.36 | N12: 634.82 | O12: 187.77 | P12: 822.59 | Q12: 995.77 | S12: Drexel Hill | T12: 19026
A13: J-20012 | B13: C-10640 | C13: Jason White | D13: Drain Cleaning | E13: Drain | F13: Standard | G13: 2024-12-11 11:36 | H13: 2024-12-11 11:36 | I13: Completed | J13: T-06 | K13: David Chen | L13: 0.69 | M13: 361.31 | N13: 44.95 | O13: 38.14 | P13: 83.09 | Q13: 278.22 | S13: King of Prussia | T13: 19494
A14: J-20013 | B14: C-10803 | C14: Gonzalez LLC | D14: Frozen Pipe Thaw | E14: Emergency | F14: Emergency | G14: 2024-11-22 14:43 | H14: 2024-11-22 14:43 | I14: Completed | J14: T-06 | K14: David Chen | L14: 1.62 | M14: 662.16 | N14: 188.98 | O14: 97.06 | P14: 286.04 | Q14: 376.12 | S14: Conshohocken | T14: 19438
A15: J-20014 | B15: C-10117 | C15: Garcia Building | D15: Drain Cleaning | E15: Drain | F15: Standard | G15: 2026-01-20 18:37 | H15: 2026-01-20 18:37 | I15: Completed | J15: T-02 | K15: Carlos Mendez | L15: 1.13 | M15: 379.58 | N15: 115.94 | O15: 54.12 | P15: 170.06 | Q15: 209.52 | R15: 5 | S15: Drexel Hill | T15: 19052
A16: J-20015 | B16: C-10827 | C16: Wright Center | D16: Faucet Replacement | E16: Install | F16: Standard | G16: 2024-12-21 03:05 | H16: 2024-12-21 03:05 | I16: Completed | J16: T-01 | K16: Mike Sullivan | L16: 1.24 | M16: 216.25 | N16: 57.09 | O16: 84.97 | P16: 142.06 | Q16: 74.19 | R16: 4 | S16: Norristown | T16: 19489
A17: J-20016 | B17: C-10084 | C17: Helen Rogers | D17: Leaking Pipe Repair | E17: Repair | F17: Standard | G17: 2024-05-04 16:47 | H17: 2024-05-04 16:47 | I17: Completed | J17: T-04 | K17: Brandon Pierce | L17: 1.12 | M17: 266.27 | N17: 90.22 | O17: 50.52 | P17: 140.74 | Q17: 125.53 | R17: 1 | S17: Ardmore | T17: 19092
A18: J-20017 | B18: C-10620 | C18: Ryan Jones | D18: Gas Line Repair | E18: Repair | F18: Standard | G18: 2025-09-29 08:00 | I18: Completed | J18: T-04 | K18: Brandon Pierce | L18: 2.7 | M18: 969.88 | N18: 309.35 | O18: 125.97 | P18: 435.32 | Q18: 534.56 | S18: Conshohocken | T18: 19491
A19: J-20018 | B19: C-10078 | C19: James White | D19: Burst Pipe Emergency | E19: Emergency | F19: Emergency | G19: 2025-10-22 11:20 | H19: 2025-10-23 11:20 | I19: Completed | J19: T-05 | K19: Anthony Russo | L19: 3.57 | M19: 740.32 | N19: 143.57 | O19: 256.27 | P19: 399.84 | Q19: 340.48 | R19: 5 | S19: Bryn Mawr | T19: 19028
A20: J-20019 | B20: C-10354 | C20: Sharon Reed | D20: Water Main Repair | E20: Emergency | F20: Emergency | G20: 2025-10-23 21:57 | H20: 2025-10-23 21:57 | I20: Completed | J20: T-07 | K20: Kevin O'Brien | L20: 8.01 | M20: 6925.42 | N20: 1919.81 | O20: 421.32 | P20: 2341.13 | Q20: 4584.29 | R20: 4 | S20: Conshohocken | T20: 19494
A21: J-20020 | B21: C-10734 | C21: Jeffrey Campbell | D21: Bathroom Remodel Plumbing | E21: Project | F21: Standard | G21: 2024-08-12 12:16 | H21: 2024-08-12 12:16 | I21: Completed | J21: T-05 | K21: Anthony Russo | L21: 16.47 | M21: 2917.79 | N21: 849.61 | O21: 780.39 | P21: 1630 | Q21: 1287.79 | R21: 5 | S21: Media | T21: 19049
A22: J-20021 | B22: C-10831 | C22: Baker Management | D22: Kitchen Remodel Plumbing | E22: Project | F22: Standard | G22: 2025-08-16 05:50 | H22: 2025-08-16 05:50 | I22: Completed | J22: T-08 | K22: Marcus Thompson | L22: 10.26 | M22: 4328.62 | N22: 1062.94 | O22: 668.07 | P22: 1731.01 | Q22: 2597.61 | S22: Ardmore | T22: 19032
A23: J-20022 | B23: C-10413 | C23: Jeffrey Kim | D23: Bathroom Remodel Plumbing | E23: Project | F23: Standard | G23: 2025-03-08 10:59 | H23: 2025-03-09 10:59 | I23: Completed | J23: T-03 | K23: Tyrese Jackson | L23: 18.46 | M23: 7758.06 | N23: 1759.61 | O23: 906.8 | P23: 2666.41 | Q23: 5091.65 | R23: 4 | S23: Conshohocken | T23: 19448
A24: J-20023 | B24: C-10678 | C24: Matthew Clark | D24: Leaking Pipe Repair | E24: Repair | F24: Standard | G24: 2025-07-03 13:48 | H24: 2025-07-03 13:48 | I24: Completed | J24: T-05 | K24: Anthony Russo | L24: 2.03 | M24: 322.65 | N24: 39.93 | O24: 117.24 | P24: 157.17 | Q24: 165.48 | S24: Chester | T24: 19055
A25: J-20024 | B25: C-10742 | C25: Brian Torres | D25: Kitchen Remodel Plumbing | E25: Project | F25: Standard | G25: 2024-05-25 22:38 | H25: 2024-05-28 22:38 | I25: Completed | J25: T-08 | K25: Marcus Thompson | L25: 17.89 | M25: 4089.64 | N25: 1381.83 | O25: 882.25 | P25: 2264.08 | Q25: 1825.56 | R25: 5 | S25: Chester | T25: 19044
A26: J-20025 | B26: C-10507 | C26: Robert Moore | D26: AC Repair | E26: HVAC | F26: Standard | G26: 2025-05-23 02:21 | H26: 2025-05-23 02:21 | I26: Completed | J26: T-05 | K26: Anthony Russo | L26: 2.12 | M26: 952.21 | N26: 252.57 | O26: 114.78 | P26: 367.35 | Q26: 584.86 | R26: 4 | S26: Ardmore | T26: 19036
A27: J-20026 | B27: C-10132 | C27: Joseph Clark | D27: Sump Pump Install | E27: Install | F27: Standard | G27: 2025-03-24 10:45 | H27: 2025-03-24 10:45 | I27: Completed | J27: T-06 | K27: David Chen | L27: 3.85 | M27: 1091.4 | N27: 249.83 | O27: 175.09 | P27: 424.92 | Q27: 666.48 | S27: Chester | T27: 19067
A28: J-20027 | B28: C-10488 | C28: Richardson Management | D28: AC Repair | E28: HVAC | F28: Standard | G28: 2025-05-12 03:24 | H28: 2025-05-15 03:24 | I28: Completed | J28: T-04 | K28: Brandon Pierce | L28: 1.91 | M28: 828.3 | N28: 232.43 | O28: 132.46 | P28: 364.89 | Q28: 463.41 | R28: 5 | S28: Philadelphia | T28: 19117
A29: J-20028 | B29: C-10020 | C29: Paul Torres | D29: Faucet Replacement | E29: Install | F29: Standard | G29: 2024-07-07 13:55 | H29: 2024-07-07 13:55 | I29: Completed | J29: T-05 | K29: Anthony Russo | L29: 1.22 | M29: 287.19 | N29: 40.78 | O29: 79.61 | P29: 120.39 | Q29: 166.8 | R29: 5 | S29: King of Prussia | T29: 19497
A30: J-20029 | B30: C-10789 | C30: Edwards Holdings | D30: Sewer Line Repair | E30: Repair | F30: Urgent | G30: 2026-04-03 13:38 | H30: 2026-04-04 13:38 | I30: Completed | J30: T-05 | K30: Anthony Russo | L30: 5.66 | M30: 5466.58 | N30: 1251.64 | O30: 288.83 | P30: 1540.47 | Q30: 3926.11 | S30: Norristown | T30: 19439
A31: J-20030 | B31: C-10322 | C31: Steven Perez | D31: Water Softener Install | E31: Install | F31: Standard | G31: 2025-09-26 04:22 | H31: 2025-09-26 04:22 | I31: Completed | J31: T-04 | K31: Brandon Pierce | L31: 3.08 | M31: 2309.86 | N31: 383.47 | O31: 206.02 | P31: 589.49 | Q31: 1720.37 | S31: Drexel Hill | T31: 19089
A32: J-20031 | B32: C-10255 | C32: Robinson Plaza | D32: AC Repair | E32: HVAC | F32: Standard | G32: 2025-06-07 23:59 | H32: 2025-06-07 23:59 | I32: Completed | J32: T-08 | K32: Marcus Thompson | L32: 1.45 | M32: 873.05 | N32: 164.64 | O32: 73.25 | P32: 237.89 | Q32: 635.16 | S32: Norristown | T32: 19490
A33: J-20032 | B33: C-10458 | C33: White Building | D33: Slab Leak Detection | E33: Diagnostic | F33: Standard | G33: 2025-05-20 20:01 | H33: 2025-05-20 20:01 | I33: Completed | J33: T-08 | K33: Marcus Thompson | L33: 2.55 | M33: 499.61 | N33: 77.99 | O33: 145.33 | P33: 223.32 | Q33: 276.29 | S33: West Chester | T33: 19323
A34: J-20033 | B34: C-10331 | C34: Ronald Ward | D34: Drain Cleaning | E34: Drain | F34: Standard | G34: 2025-03-18 06:59 | H34: 2025-03-18 06:59 | I34: Completed | J34: T-06 | K34: David Chen | L34: 1.36 | M34: 317.62 | N34: 65.06 | O34: 72.78 | P34: 137.84 | Q34: 179.78 | S34: Chester | T34: 19092
A35: J-20034 | B35: C-10660 | C35: Brandon Thomas | D35: Garbage Disposal Install | E35: Install | F35: Standard | G35: 2024-10-30 22:14 | H35: 2024-10-30 22:14 | I35: Completed | J35: T-02 | K35: Carlos Mendez | L35: 2.03 | M35: 362.76 | N35: 106.65 | O35: 93.51 | P35: 200.16 | Q35: 162.6 | R35: 5 | S35: Media | T35: 19054
A36: J-20035 | B36: C-10731 | C36: Martinez Holdings | D36: Sewer Line Inspection | E36: Diagnostic | F36: Standard | G36: 2026-01-25 08:35 | H36: 2026-01-25 08:35 | I36: Completed | J36: T-07 | K36: Kevin O'Brien | L36: 1.2 | M36: 296.42 | N36: 41.1 | O36: 65.13 | P36: 106.23 | Q36: 190.19 | S36: Norristown | T36: 19464
A37: J-20036 | B37: C-10092 | C37: Jeffrey Ward | D37: Furnace Repair | E37: HVAC | F37: Standard | G37: 2025-07-13 16:45 | H37: 2025-07-13 16:45 | I37: Completed | J37: T-04 | K37: Brandon Pierce | L37: 2.26 | M37: 382.51 | N37: 59.89 | O37: 148.24 | P37: 208.13 | Q37: 174.38 | R37: 4 | S37: King of Prussia | T37: 19478
A38: J-20037 | B38: C-10157 | C38: Clark Center | D38: Boiler Repair | E38: HVAC | F38: Standard | G38: 2024-10-31 14:29 | H38: 2024-10-31 14:29 | I38: Completed | J38: T-02 | K38: Carlos Mendez | L38: 3.43 | M38: 760.97 | N38: 202.34 | O38: 191.01 | P38: 393.35 | Q38: 367.62 | S38: Drexel Hill | T38: 19018
A39: J-20038 | B39: C-10214 | C39: Alexander Walker | D39: Sewer Line Inspection | E39: Diagnostic | F39: Standard | G39: 2024-08-19 12:28 | H39: 2024-08-20 12:28 | I39: Completed | J39: T-01 | K39: Mike Sullivan | L39: 1.17 | M39: 341.55 | N39: 41.55 | O39: 74.82 | P39: 116.37 | Q39: 225.18 | S39: Wayne | T39: 19057
A40: J-20039 | B40: C-10289 | C40: Ronald Gonzalez | D40: Sewer Line Repair | E40: Repair | F40: Standard | G40: 2025-04-29 17:40 | H40: 2025-04-30 17:40 | I40: Completed | J40: T-08 | K40: Marcus Thompson | L40: 4.32 | M40: 2593.36 | N40: 431.44 | O40: 265.27 | P40: 696.71 | Q40: 1896.65 | S40: Wayne | T40: 19070
...

Sheet Invoices
A1: Invoice ID | B1: Job ID | C1: Customer ID | D1: Customer Name | E1: Invoice Date | F1: Subtotal | G1: Tax | H1: Total | I1: Paid | J1: Paid Date | K1: Days to Pay | L1: Payment Method | M1: Status
A2: INV-50001 | B2: J-20001 | C2: C-10432 | D2: Karen Hill | E2: 2024-05-25 | F2: 665.95 | G2: 53.28 | H2: 719.23 | I2: Yes | J2: 2024-05-25 | K2: 0 | L2: Credit Card | M2: Paid
A3: INV-50002 | B3: J-20002 | C3: C-10747 | D3: Michelle Hernandez | E3: 2025-02-12 | F3: 3927.93 | G3: 314.23 | H3: 4242.16 | I3: Yes | J3: 2025-02-15 | K3: 3 | L3: ACH | M3: Paid
A4: INV-50003 | B4: J-20003 | C4: C-10794 | D4: Anthony Flores | E4: 2025-03-09 | F4: 569.33 | G4: 45.55 | H4: 614.88 | I4: Yes | J4: 2025-04-08 | K4: 30 | L4: ACH | M4: Paid
A5: INV-50004 | B5: J-20004 | C5: C-10697 | D5: Adams Management | E5: 2025-09-16 | F5: 257.31 | G5: 20.58 | H5: 277.89 | I5: Yes | J5: 2025-09-23 | K5: 7 | L5: Credit Card | M5: Paid
A6: INV-50005 | B6: J-20005 | C6: C-10628 | D6: Cruz Group | E6: 2026-03-30 | F6: 763.09 | G6: 61.05 | H6: 824.14 | I6: Yes | J6: 2026-05-29 | K6: 60 | L6: Financing | M6: Paid
A7: INV-50006 | B7: J-20006 | C7: C-10315 | D7: Scott Hill | E7: 2025-01-04 | F7: 275.18 | G7: 22.01 | H7: 297.19 | I7: Yes | J7: 2025-01-05 | K7: 1 | L7: Cash | M7: Paid
A8: INV-50007 | B8: J-20007 | C8: C-10546 | D8: Mary Davis | E8: 2025-07-27 | F8: 2004.42 | G8: 160.35 | H8: 2164.77 | I8: Yes | J8: 2025-07-30 | K8: 3 | L8: Credit Card | M8: Paid
A9: INV-50008 | B9: J-20011 | C9: C-10171 | D9: Sarah Evans | E9: 2025-07-01 | F9: 1818.36 | G9: 145.47 | H9: 1963.83 | I9: Yes | J9: 2025-07-02 | K9: 1 | L9: Credit Card | M9: Paid
A10: INV-50009 | B10: J-20012 | C10: C-10640 | D10: Jason White | E10: 2024-12-11 | F10: 361.31 | G10: 28.9 | H10: 390.21 | I10: Yes | J10: 2024-12-12 | K10: 1 | L10: Credit Card | M10: Paid
A11: INV-50010 | B11: J-20013 | C11: C-10803 | D11: Gonzalez LLC | E11: 2024-11-22 | F11: 662.16 | G11: 52.97 | H11: 715.13 | I11: Yes | J11: 2024-11-29 | K11: 7 | L11: Check | M11: Paid
A12: INV-50011 | B12: J-20014 | C12: C-10117 | D12: Garcia Building | E12: 2026-01-20 | F12: 379.58 | G12: 30.37 | H12: 409.95 | I12: Yes | J12: 2026-01-23 | K12: 3 | L12: Credit Card | M12: Paid
A13: INV-50012 | B13: J-20015 | C13: C-10827 | D13: Wright Center | E13: 2024-12-21 | F13: 216.25 | G13: 17.3 | H13: 233.55 | I13: Yes | J13: 2024-12-21 | K13: 0 | L13: Check | M13: Paid
... A30: INV-50029 | B30: J-20032 | C30: C-10458 | D30: White Building | E30: 2025-05-20 | F30: 499.61 | G30: 39.97 | H30: 539.58 | I30: Yes | J30: 2025-05-20 | K30: 0 | L30: Credit Card | M30: Paid
A31: INV-50030 | B31: J-20033 | C31: C-10331 | D31: Ronald Ward | E31: 2025-03-18 | F31: 317.62 | G31: 25.41 | H31: 343.03 | I31: No | M31: Open
A32: INV-50031 | B32: J-20034 | C32: C-10660 | D32: Brandon Thomas | E32: 2024-10-30 | F32: 362.76 | G32: 29.02 | H32: 391.78 | I32: Yes | J32: 2024-11-02 | K32: 3 | L32: Check | M32: Paid
A33: INV-50032 | B33: J-20035 | C33: C-10731 | D33: Martinez Holdings | E33: 2026-01-25 | F33: 296.42 | G33: 23.71 | H33: 320.13 | I33: Yes | J33: 2026-01-25 | K33: 0 | L33: Check | M33: Paid
A34: INV-50033 | B34: J-20036 | C34: C-10092 | D34: Jeffrey Ward | E34: 2025-07-13 | F34: 382.51 | G34: 30.6 | H34: 413.11 | I34: Yes | J34: 2025-07-16 | K34: 3 | L34: Credit Card | M34: Paid
A35: INV-50034 | B35: J-20037 | C35: C-10157 | D35: Clark Center | E35: 2024-10-31 | F35: 760.97 | G35: 60.88 | H35: 821.85 | I35: No | M35: Open
A36: INV-50035 | B36: J-20038 | C36: C-10214 | D36: Alexander Walker | E36: 2024-08-20 | F36: 341.55 | G36: 27.32 | H36: 368.87 | I36: Yes | J36: 2024-09-19 | K36: 30 | L36: Check | M36: Paid
A37: INV-50036 | B37: J-20039 | C37: C-10289 | D37: Ronald Gonzalez | E37: 2025-04-30 | F37: 2593.36 | G37: 207.47 | H37: 2800.83 | I37: Yes | J37: 2025-05-03 | K37: 3 | L37: Financing | M37: Paid
A38: INV-50037 | B38: J-20040 | C38: C-10668 | D38: Benjamin Flores | E38: 2026-02-23 | F38: 3206.28 | G38: 256.5 | H38: 3462.78 | I38: Yes | J38: 2026-02-24 | K38: 1 | L38: Credit Card | M38: Paid
A39: INV-50038 | B39: J-20041 | C39: C-10608 | D39: Thompson Building | E39: 2025-07-22 | F39: 717.35 | G39: 57.39 | H39: 774.74 | I39: No | M39: Open
A40: INV-50039 | B40: J-20044 | C40: C-10221 | D40: Linda Kim | E40: 2026-01-19 | F40: 442.24 | G40: 35.38 | H40: 477.62 | I40: Yes | J40: 2026-03-20 | K40: 60 | L40: Credit Card | M40: Paid
A41: INV-50040 | B41: J-20045 | C41: C-10820 | D41: Peterson Properties | E41: 2024-12-05 | F41: 1785.06 | G41: 142.8 | H41: 1927.86 | I41: Yes | J41: 2024-12-08 | K41: 3 | L41: Check | M41: Paid
A42: INV-50041 | B42: J-20046 | C42: C-10492 | D42: Thompson Apartments | E42: 2024-05-12 | F42: 404.43 | G42: 32.35 | H42: 436.78 | I42: Yes | J42: 2024-05-12 | K42: 0 | L42: Cash | M42: Paid
A43: INV-50042 | B43: J-20047 | C43: C-10046 | D43: Kim Management | E43: 2025-07-07 | F43: 2594.18 | G43: 207.53 | H43: 2801.71 | I43: Yes | J43: 2025-08-06 | K43: 30 | L43: Check | M43: Paid
A44: INV-50043 | B44: J-20048 | C44: C-10046 | D44: Kim Management | E44: 2024-04-17 | F44: 958.61 | G44: 76.69 | H44: 1035.3 | I44: Yes | J44: 2024-04-17 | K44: 0 | L44: Check | M44: Paid
A45: INV-50044 | B45: J-20049 | C45: C-10558 | D45: Ronald Gomez | E45: 2024-06-21 | F45: 551.79 | G45: 44.14 | H45: 595.93 | I45: Yes | J45: 2024-06-24 | K45: 3 | L45: Check | M45: Paid
A46: INV-50045 | B46: J-20050 | C46: C-10507 | D46: Robert Moore | E46: 2024-07-29 | F46: 3287.01 | G46: 262.96 | H46: 3549.97 | I46: Yes | J46: 2024-07-29 | K46: 0 | L46: ACH | M46: Paid
A47: INV-50046 | B47: J-20052 | C47: C-10406 | D47: Carter LLC | E47: 2024-09-26 | F47: 432.03 | G47: 34.56 | H47: 466.59 | I47: No | M47: Open
A48: INV-50047 | B48: J-20053 | C48: C-10807 | D48: Stephen Collins | E48: 2024-10-18 | F48: 352.29 | G48: 28.18 | H48: 380.47 | I48: Yes | J48: 2024-12-17 | K48: 60 | L48: Financing | M48: Paid
A49: INV-50048 | B49: J-20055 | C49: C-10311 | D49: Susan Perez | E49: 2025-06-08 | F49: 948.18 | G49: 75.85 | H49: 1024.03 | I49: Yes | J49: 2025-06-11 | K49: 3 | L49: Credit Card | M49: Paid
A50: INV-50049 | B50: J-20056 | C50: C-10678 | D50: Matthew Clark | E50: 2025-03-19 | F50: 227.75 | G50: 18.22 | H50: 245.97 | I50: Yes | J50: 2025-03-20 | K50: 1 | L50: Credit Card | M50: Paid
A51: INV-50050 | B51: J-20058 | C51: C-10390 | D51: Ashley Adams | E51: 2025-07-22 | F51: 2797.88 | G51: 223.83 | H51: 3021.71 | I51: Yes | J51: 2025-08-21 | K51: 30 | L51: ACH | M51: Paid
A52: INV-50051 | B52: J-20059 | C52: C-10248 | D52: Miller Apartments | E52: 2025-08-28 | F52: 1621.78 | G52: 129.74 | H52: 1751.52 | I52: Yes | J52: 2025-08-31 | K52: 3 | L52: Check | M52: Paid
A53: INV-50052 | B53: J-20060 | C53: C-10515 | D53: Robinson Realty | E53: 2024-10-05 | F53: 433.43 | G53: 34.67 | H53: 468.1 | I53: No | M53: Open
A54: INV-50053 | B54: J-20061 | C54: C-10167 | D54: Laura Cruz | E54: 2025-09-15 | F54: 1603.54 | G54: 128.28 | H54: 1731.82 | I54: Yes | J54: 2025-10-15 | K54: 30 | L54: Financing | M54: Paid
A55: INV-50054 | B55: J-20062 | C55: C-10349 | D55: Paul Jackson | E55: 2025-01-06 | F55: 1093.41 | G55: 87.47 | H55: 1180.88 | I55: Yes | J55: 2025-01-06 | K55: 0 | L55: ACH | M55: Paid
A56: INV-50055 | B56: J-20063 | C56: C-10022 | D56: Sharon Taylor | E56: 2025-06-25 | F56: 934.13 | G56: 74.73 | H56: 1008.86 | I56: Yes | J56: 2025-07-09 | K56: 14 | L56: ACH | M56: Paid
...

Sheet Calls
A1: Call ID | B1: Timestamp | C1: Phone | D1: Duration (min) | E1: Answered | F1: After Hours | G1: Lead Source | H1: Intent | I1: Booked | J1: Converted | K1: Revenue Attributed
A2: CL-30001 | B2: 2025-12-21 23:05 | C2: (380) 569-8067 | D2: 3.9 | E2: Yes | F2: Yes | G2: HomeAdvisor | H2: Leak | I2: Yes | J2: No | K2: 0
A3: CL-30002 | B3: 2026-01-16 15:43 | C3: (247) 259-4125 | D3: 2.5 | E3: Yes | F3: No | G3: Direct Mail | H3: Drain Clog | I3: Yes | J3: No | K3: 0
A4: CL-30003 | B4: 2025-11-25 20:39 | C4: (295) 456-1619 | D4: 5.2 | E4: Yes | F4: Yes | G4: Repeat Customer | H4: Burst Pipe | I4: Yes | J4: Yes | K4: 3107.96
A5: CL-30004 | B5: 2025-02-15 00:39 | C5: (425) 278-3158 | D5: 5.5 | E5: No | F5: Yes | G5: Yelp | H5: Other | I5: No | J5: No | K5: 0
A6: CL-30005 | B6: 2025-12-01 11:08 | C6: (254) 265-3698 | D6: 5.9 | E6: Yes | F6: No | G6: Google Ads | H6: Drain Clog | I6: No | J6: No | K6: 0
A7: CL-30006 | B7: 2025-09-06 16:16 | C7: (535) 599-8613 | D7: 0.3 | E7: Yes | F7: Yes | G7: HomeAdvisor | H7: HVAC | I7: Yes | J7: Yes | K7: 3144.86
A8: CL-30007 | B8: 2025-07-29 18:46 | C8: (473) 514-2629 | D8: 1.3 | E8: No | F8: Yes | G8: Referral | H8: Sewer | I8: No | J8: No | K8: 0
A9: CL-30008 | B9: 2025-06-10 16:41 | C9: (226) 967-8973 | D9: 3.3 | E9: Yes | F9: No | G9: Facebook | H9: Burst Pipe | I9: No | J9: No | K9: 0
A10: CL-30009 | B10: 2025-07-10 02:22 | C10: (588) 828-7016 | D10: 3.1 | E10: Yes | F10: Yes | G10: Google Search | H10: HVAC | I10: No | J10: No | K10: 0
A11: CL-30010 | B11: 2026-03-30 04:12 | C11: (483) 856-2125 | D11: 2.8 | E11: No | F11: Yes | G11: Repeat Customer | H11: Leak | I11: No | J11: No | K11: 0
A12: CL-30011 | B12: 2025-01-15 06:46 | C12: (277) 251-7106 | D12: 2.7 | E12: Yes | F12: Yes | G12: Truck Signage | H12: Leak | I12: Yes | J12: Yes | K12: 1589.93
A13: CL-30012 | B13: 2026-01-15 12:13 | C13: (388) 544-2492 | D13: 5.3 | E13: Yes | F13: No | G13: Google Search | H13: HVAC | I13: No | J13: No | K13: 0
... A3201: CL-33200 | B3201: 2025-12-15 06:05 | C3201: (557) 478-6731 | D3201: 2.8 | E3201: Yes | F3201: Yes | G3201: Google Search | H3201: Drain Clog | I3201: Yes | J3201: Yes | K3201: 329.93

Sheet Reviews
A1: Review ID | B1: Date | C1: Platform | D1: Stars | E1: Review Text | F1: Responded | G1: Tech Mentioned
A2: R-40001 | B2: 2025-11-07 | C2: Yelp | D2: 5 | E2: Showed up on time and fixed the problem fast. | F2: Yes
A3: R-40002 | B3: 2025-12-13 | C3: Google | D3: 5 | E3: Fixed our water heater in under 2 hours. Great service. | F3: Yes
A4: R-40003 | B4: 2025-06-20 | C4: Angi | D4: 5 | E4: Fixed our water heater in under 2 hours. Great service. | F4: Yes
A5: R-40004 | B5: 2024-05-23 | C5: Google | D5: 5 | E5: Tech was professional and explained everything. | F5: Yes
A6: R-40005 | B6: 2025-02-10 | C6: Google | D6: 5 | E6: They came the same day for an emergency. Lifesavers. | F6: Yes | G6: Kevin O'Brien
A7: R-40006 | B7: 2025-08-21 | C7: Google | D7: 4 | E7: Mike was awesome — knowledgeable and friendly. | F7: Yes
A8: R-40007 | B8: 2024-06-19 | C8: Google | D8: 5 | E8: Fair price and great work. Will use again. | F8: Yes | G8: David Chen
A9: R-40008 | B9: 2026-01-08 | C9: Google | D9: 3 | E9: Work was solid but the wait window was too long. | F9: Yes | G9: Anthony Russo
A10: R-40009 | B10: 2025-05-04 | C10: BBB | D10: 5 | E10: Best plumbing experience I've had in Philly. A+. | F10: Yes
A11: R-40010 | B11: 2024-10-05 | C11: Google | D11: 5 | E11: Quick response, clean work, no upselling. | F11: Yes
A12: R-40011 | B12: 2024-12-14 | C12: Google | D12: 5 | E12: Mike was awesome — knowledgeable and friendly. | F12: Yes
A13: R-40012 | B13: 2025-05-08 | C13: Google | D13: 5 | E13: Fair price and great work. Will use again. | F13: Yes
A14: R-40013 | B14: 2025-10-11 | C14: Angi | D14: 5 | E14: Showed up on time and fixed the problem fast. | F14: Yes
A15: R-40014 | B15: 2024-06-29 | C15: Yelp | D15: 4 | E15: Quote was exactly what they charged. No surprises. | F15: Yes | G15: Tyrese Jackson
A16: R-40015 | B16: 2025-03-08 | C16: Google | D16: 5 | E16: Highly recommend Keystone — saved us from a flood at 2am. | F16: Yes
A17: R-40016 | B17: 2025-05-27 | C17: Angi | D17: 5 | E17: Fair price and great work. Will use again. | F17: Yes
A18: R-40017 | B18: 2024-07-22 | C18: Yelp | D18: 5 | E18: Highly recommend Keystone — saved us from a flood at 2am. | F18: Yes | G18: Carlos Mendez
A19: R-40018 | B19: 2025-08-17 | C19: Yelp | D19: 5 | E19: Quote was exactly what they charged. No surprises. | F19: Yes | G19: Kevin O'Brien
A20: R-40019 | B20: 2025-05-12 | C20: Google | D20: 5 | E20: Tech was professional and explained everything. | F20: Yes
A21: R-40020 | B21: 2026-03-20 | C21: Google | D21: 5 | E21: Showed up on time and fixed the problem fast. | F21: Yes
A22: R-40021 | B22: 2024-07-26 | C22: Google | D22: 5 | E22: They came the same day for an emergency. Lifesavers. | F22: Yes
A23: R-40022 | B23: 2024-05-24 | C23: Google | D23: 4 | E23: Quick response, clean work, no upselling. | F23: Yes
A24: R-40023 | B24: 2024-07-10 | C24: Google | D24: 5 | E24: Highly recommend Keystone — saved us from a flood at 2am. | F24: Yes
A25: R-40024 | B25: 2024-05-21 | C25: Google | D25: 5 | E25: Fair price and great work. Will use again. | F25: Yes
A26: R-40025 | B26: 2025-04-25 | C26: Yelp | D26: 5 | E26: They came the same day for an emergency. Lifesavers. | F26: No | G26: Tyrese Jackson
A27: R-40026 | B27: 2024-07-10 | C27: Facebook | D27: 5 | E27: Highly recommend Keystone — saved us from a flood at 2am. | F27: Yes | G27: Carlos Mendez
A28: R-40027 | B28: 2024-05-06 | C28: Google | D28: 5 | E28: Quote was exactly what they charged. No surprises. | F28: Yes
A29: R-40028 | B29: 2024-07-25 | C29: Google | D29: 4 | E29: Quote was exactly what they charged. No surprises. | F29: Yes | G29: Brandon Pierce
A30: R-40029 | B30: 2025-12-09 | C30: Yelp | D30: 5 | E30: They came the same day for an emergency. Lifesavers. | F30: Yes
A31: R-40030 | B31: 2025-05-30 | C31: Google | D31: 5 | E31: Quote was exactly what they charged. No surprises. | F31: No
A32: R-40031 | B32: 2025-04-21 | C32: Yelp | D32: 5 | E32: Tech was professional and explained everything. | F32: Yes
A33: R-40032 | B33: 2025-12-14 | C33: Yelp | D33: 5 | E33: Fair price and great work. Will use again. | F33: Yes
A34: R-40033 | B34: 2026-02-10 | C34: BBB | D34: 5 | E34: Quote was exactly what they charged. No surprises. | F34: Yes
A35: R-40034 | B35: 2024-07-16 | C35: Google | D35: 5 | E35: Highly recommend Keystone — saved us from a flood at 2am. | F35: No
A36: R-40035 | B36: 2025-04-28 | C36: Angi | D36: 5 | E36: Highly recommend Keystone — saved us from a flood at 2am. | F36: Yes | G36: Tyrese Jackson
A37: R-40036 | B37: 2024-11-17 | C37: Google | D37: 5 | E37: Fair price and great work. Will use again. | F37: Yes
A38: R-40037 | B38: 2024-05-08 | C38: Yelp | D38: 5 | E38: Quote was exactly what they charged. No surprises. | F38: Yes
A39: R-40038 | B39: 2025-10-30 | C39: Google | D39: 5 | E39: Highly recommend Keystone — saved us from a flood at 2am. | F39: Yes | G39: Anthony Russo
A40: R-40039 | B40: 2024-10-28 | C40: Google | D40: 5 | E40: Fair price and great work. Will use again. | F40: Yes
...

Sheet Technicians
A1: Tech ID | B1: Name | C1: License | D1: Level | E1: Years Experience | F1: Avg Rating
A2: T-01 | B2: Mike Sullivan | C2: Master Plumber | D2: Senior | E2: 18 | F2: 4.9
A3: T-02 | B3: Carlos Mendez | C3: Journeyman | D3: Senior | E3: 11 | F3: 4.8
A4: T-03 | B4: Tyrese Jackson | C4: Journeyman | D4: Mid | E4: 6 | F4: 4.7
A5: T-04 | B5: Brandon Pierce | C5: Journeyman | D5: Mid | E5: 7 | F5: 4.6
A6: T-05 | B6: Anthony Russo | C6: Apprentice | D6: Junior | E6: 2 | F6: 4.5
A7: T-06 | B7: David Chen | C7: Master Plumber | D7: Senior | E7: 15 | F7: 4.9
A8: T-07 | B8: Kevin O'Brien | C8: Journeyman | D8: Mid | E8: 9 | F8: 4.4
A9: T-08 | B9: Marcus Thompson | C9: Apprentice | D9: Junior | E9: 3 | F9: 4.6

Sheet Parts Inventory
A1: Part ID | B1: Description | C1: Category | D1: Unit Cost | E1: On Hand
A2: P-1001 | B2: 1/2" Copper Pipe (10ft) | C2: Pipe | D2: 18.5 | E2: 42
A3: P-1002 | B3: 3/4" Copper Pipe (10ft) | C3: Pipe | D3: 26.75 | E3: 38
A4: P-1003 | B4: 1" PVC Pipe (10ft) | C4: Pipe | D4: 8.25 | E4: 75
A5: P-1004 | B5: Wax Toilet Ring | C5: Toilet | D5: 4.5 | E5: 120
A6: P-1005 | B6: Toilet Flapper | C6: Toilet | D6: 6.25 | E6: 85
A7: P-1006 | B7: Toilet Fill Valve | C7: Toilet | D7: 14.5 | E7: 60
A8: P-1007 | B8: 40-Gal Gas Water Heater | C8: Water Heater | D8: 685 | E8: 8
A9: P-1008 | B9: 50-Gal Gas Water Heater | C9: Water Heater | D9: 825 | E9: 6
A10: P-1009 | B10: Tankless Water Heater | C10: Water Heater | D10: 1685 | E10: 4
A11: P-1010 | B11: Garbage Disposal 3/4 HP | C11: Disposal | D11: 185 | E11: 12
A12: P-1011 | B12: Kitchen Faucet (Standard) | C12: Faucet | D12: 125 | E12: 18
A13: P-1012 | B13: Bathroom Faucet (Standard) | C13: Faucet | D13: 85 | E13: 22
... A26: P-1025 | B26: Pipe Insulation (10ft) | C26: Insulation | D26: 12.25 | E26: 40

Sheet Summary KPIs
A1: KEYSTONE PLUMBING — KPI SUMMARY
A3: REVENUE
A4: Total Revenue (all time) | B4: =SUM(Jobs!M2:M2401) -> 3288961.8
A5: Total Margin | B5: =SUM(Jobs!Q2:Q2401) -> 2028348.8
A6: Margin % | B6: =SUM(Jobs!Q2:Q2401)/SUM(Jobs!M2:M2401) -> 0.61671401
A7: Average Job Ticket | B7: =AVERAGE(Jobs!M2:M2401) -> 1370.4008
A9: JOBS
A10: Total Jobs | B10: =COUNTA(Jobs!A2:A2401) -> 2400
A11: Completed Jobs | B11: =COUNTIF(Jobs!I2:I2401,"Completed") -> 2266
A12: Cancelled Jobs | B12: =COUNTIF(Jobs!I2:I2401,"Cancelled") -> 72
A13: No-Shows | B13: =COUNTIF(Jobs!I2:I2401,"No-Show") -> 20
A15: CUSTOMERS
A16: Total Customers | B16: =COUNTA(Customers!A2:A851) -> 850
A17: Residential | B17: =COUNTIF(Customers!C2:C851,"Residential") -> 570
A18: Commercial | B18: =COUNTIF(Customers!C2:C851,"Commercial") -> 179
A19: Property Mgmt | B19: =COUNTIF(Customers!C2:C851,"Property Mgmt") -> 101
A21: CALLS / LEADS
A22: Total Inbound Calls | B22: =COUNTA(Calls!A2:A3201) -> 3200
A23: Calls Answered | B23: =COUNTIF(Calls!E2:E3201,"Yes") -> 2292
A24: Answer Rate | B24: =COUNTIF(Calls!E2:E3201,"Yes")/COUNTA(Calls!A2:A3201) -> 0.71625
A25: After-Hours Calls | B25: =COUNTIF(Calls!F2:F3201,"Yes") -> 2147
A26: Calls Booked | B26: =COUNTIF(Calls!I2:I3201,"Yes") -> 1093
A27: Booking Rate (of answered) | B27: =COUNTIF(Calls!I2:I3201,"Yes")/COUNTIF(Calls!E2:E3201,"Yes") -> 0.47687609
A28: Missed-Call Revenue Risk (est) | B28: =(COUNTA(Calls!A2:A3201)-COUNTIF(Calls!E2:E3201,"Yes"))*AVERAGEIF(Calls!J2:J3201,"Yes",Calls!K2:K3201)*0.4 -> 621163.53
A30: REVIEWS
A31: Total Reviews | B31: =COUNTA(Reviews!A2:A421) -> 420
A32: Average Stars | B32: =AVERAGE(Reviews!D2:D421) -> 4.5
A33: 5-Star Reviews | B33: =COUNTIF(Reviews!D2:D421,5) -> 295
A34: 1-2 Star Reviews | B34: =COUNTIF(Reviews!D2:D421,"<=2") -> 27
A35: Response Rate | B35: =COUNTIF(Reviews!F2:F421,"Yes")/COUNTA(Reviews!A2:A421) -> 0.81428571
A37: INVOICES
A38: Total Invoiced | B38: =SUM(Invoices!H2:H2267) -> 3365773.7
A39: Outstanding (Open + Overdue) | B39: =SUMIFS(Invoices!H2:H2267,Invoices!I2:I2267,"No") -> 176286.59
A40: Avg Days to Pay | B40: =AVERAGEIF(Invoices!I2:I2267,"Yes",Invoices!K2:K2267) -> 9.4073901
